<?xml version="1.0" encoding="utf-8"?>
<robot name="rm_75_dual_description">

  <link name="torso_base_link">
    <visual>
      <origin xyz="0 0 0" rpy="0 0 0"/>
      <geometry>
        <box size="0.1 0.1 0.1"/>
      </geometry>
      <material name="Grey">
        <color rgba="0.7 0.7 0.7 1.0"/>
      </material>
    </visual>
  </link>

  <joint name="left_base_mounting_joint" type="fixed">
    <origin xyz="0 0.1 0" rpy="-1.5708 -1.5708 -0.4363" />
    <parent link="torso_base_link" />
    <child link="left_base_link" />
  </joint>

  <link name="left_base_link">
    <inertial>
      <origin xyz="0.00043296 3.5291E-05 0.059942" rpy="0 0 0" />
      <mass value="0.84105" />
      <inertia ixx="0.0017261" ixy="2.5275E-06" ixz="3.6769E-05" iyy="0.0017099" iyz="-1.68E-06" izz="0.00090402" />
    </inertial>
    <visual>
      <origin xyz="0 0 0" rpy="0 0 0" />
      <geometry>
        <mesh filename="../meshes/base_link.STL" />
      </geometry>
      <material name="">
        <color rgba="1 1 1 1" />
      </material>
    </visual>
    <collision>
      <origin xyz="0 0 0" rpy="0 0 0" />
      <geometry>
        <mesh filename="../meshes/base_link.STL" />
      </geometry>
    </collision>
  </link>

  <link name="left_Link1">
    <inertial>
      <origin xyz="-2.1376E-07 0.025186 -0.021108" rpy="0 0 0" />
      <mass value="0.59356" />
      <inertia ixx="0.0012661" ixy="-9.8019E-09" ixz="-1.2951E-08" iyy="0.00056135" iyz="-0.00021122" izz="0.0011817" />
    </inertial>
    <visual>
      <origin xyz="0 0 0" rpy="0 0 0" />
      <geometry>
        <mesh filename="../meshes/Link1.STL" />
      </geometry>
      <material name="">
        <color rgba="1 1 1 1" />
      </material>
    </visual>
    <collision>
      <origin xyz="0 0 0" rpy="0 0 0" />
      <geometry>
        <mesh filename="../meshes/Link1.STL" />
      </geometry>
    </collision>
  </link>

  <joint name="left_joint1" type="revolute">
    <origin xyz="0 0 0.2405" rpy="-1.5708 0 0" />
    <parent link="left_base_link" />
    <child link="left_Link1" />
    <axis xyz="0 -1 0" />
    <limit lower="-3.107" upper="3.107" effort="100" velocity="1" />
  </joint>

  <link name="left_Link2">
    <inertial>
      <origin xyz="4.1111E-07 0.011078 0.076129" rpy="0 0 0" />
      <mass value="0.43285" />
      <inertia ixx="0.0012584" ixy="5.6315E-09" ixz="1.3348E-09" iyy="0.0012225" iyz="0.000279" izz="0.00031747" />
    </inertial>
    <visual>
      <origin xyz="0 0 0" rpy="0 0 0" />
      <geometry>
        <mesh filename="../meshes/Link2.STL" />
      </geometry>
      <material name="">
        <color rgba="1 1 1 1" />
      </material>
    </visual>
    <collision>
      <origin xyz="0 0 0" rpy="0 0 0" />
      <geometry>
        <mesh filename="../meshes/Link2.STL" />
      </geometry>
    </collision>
  </link>

  <joint name="left_joint2" type="revolute">
    <origin xyz="0 0 0" rpy="1.5708 0 0" />
    <parent link="left_Link1" />
    <child link="left_Link2" />
    <axis xyz="0 1 0" />
    <limit lower="-2.269" upper="2.269" effort="100" velocity="1" />
  </joint>

  <link name="left_Link3">
    <inertial>
      <origin xyz="-4.7932E-07 0.027347 -0.023544" rpy="0 0 0" />
      <mass value="0.43132" />
      <inertia ixx="0.00079433" ixy="1.0334E-08" ixz="-2.329E-09" iyy="0.00031507" iyz="-0.00014262" izz="0.00073037" />
    </inertial>
    <visual>
      <origin xyz="0 0 0" rpy="0 0 0" />
      <geometry>
        <mesh filename="../meshes/Link3.STL" />
      </geometry>
      <material name="">
        <color rgba="1 1 1 1" />
      </material>
    </visual>
    <collision>
      <origin xyz="0 0 0" rpy="0 0 0" />
      <geometry>
        <mesh filename="../meshes/Link3.STL" />
      </geometry>
    </collision>
  </link>

  <joint name="left_joint3" type="revolute">
    <origin xyz="0 0 0.256" rpy="-1.5708 0 0" />
    <parent link="left_Link2" />
    <child link="left_Link3" />
    <axis xyz="0 -1 0" />
    <limit lower="-3.107" upper="3.107" effort="100" velocity="1" />
  </joint>

  <link name="left_Link4">
    <inertial>
      <origin xyz="5.0444E-06 0.010569 0.059593" rpy="0 0 0" />
      <mass value="0.28963" />
      <inertia ixx="0.00063737" ixy="-3.8666E-08" ixz="7.0522E-08" iyy="0.00061418" iyz="0.00014461" izz="0.00015648" />
    </inertial>
    <visual>
      <origin xyz="0 0 0" rpy="0 0 0" />
      <geometry>
        <mesh filename="../meshes/Link4.STL" />
      </geometry>
      <material name="">
        <color rgba="1 1 1 1" />
      </material>
    </visual>
    <collision>
      <origin xyz="0 0 0" rpy="0 0 0" />
      <geometry>
        <mesh filename="../meshes/Link4.STL" />
      </geometry>
    </collision>
  </link>

  <joint name="left_joint4" type="revolute">
    <origin xyz="0 0 0" rpy="1.5708 0 0" />
    <parent link="left_Link3" />
    <child link="left_Link4" />
    <axis xyz="0 1 0" />
    <limit lower="-2.356" upper="2.356" effort="100" velocity="1" />
  </joint>

  <link name="left_Link5">
    <inertial>
      <origin xyz="1.1466E-06 0.021541 -0.018041" rpy="0 0 0" />
      <mass value="0.23941" />
      <inertia ixx="0.00028594" ixy="1.8435E-09" ixz="2.6611E-09" iyy="0.00011989" iyz="-4.4238E-05" izz="0.00026273" />
    </inertial>
    <visual>
      <origin xyz="0 0 0" rpy="0 0 0" />
      <geometry>
        <mesh filename="../meshes/Link5.STL" />
      </geometry>
      <material name="">
        <color rgba="1 1 1 1" />
      </material>
    </visual>
    <collision>
      <origin xyz="0 0 0" rpy="0 0 0" />
      <geometry>
        <mesh filename="../meshes/Link5.STL" />
      </geometry>
    </collision>
  </link>

  <joint name="left_joint5" type="revolute">
    <origin xyz="0 0 0.21" rpy="-1.5708 0 0" />
    <parent link="left_Link4" />
    <child link="left_Link5" />
    <axis xyz="0 -1 0" />
    <limit lower="-3.107" upper="3.107" effort="100" velocity="1" />
  </joint>

  <link name="left_Link6">
    <inertial>
      <origin xyz="4.5754E-06 0.0073681 0.059382" rpy="0 0 0" />
      <mass value="0.21879" />
      <inertia ixx="0.00035053" ixy="-1.7437E-08" ixz="3.1653E-08" iyy="0.00033447" iyz="7.824E-05" izz="0.00010492" />
    </inertial>
    <visual>
      <origin xyz="0 0 0" rpy="0 0 0" />
      <geometry>
        <mesh filename="../meshes/Link6.STL" />
      </geometry>
      <material name="">
        <color rgba="1 1 1 1" />
      </material>
    </visual>
    <collision>
      <origin xyz="0 0 0" rpy="0 0 0" />
      <geometry>
        <mesh filename="../meshes/Link6.STL" />
      </geometry>
    </collision>
  </link>

  <joint name="left_joint6" type="revolute">
    <origin xyz="0 0 0" rpy="1.5708 0 0" />
    <parent link="left_Link5" />
    <child link="left_Link6" />
    <axis xyz="0 1 0" />
    <limit lower="-2.234" upper="2.234" effort="100" velocity="1" />
  </joint>

  <link name="left_Link7">
    <inertial>
      <origin xyz="0.00032231 -0.0001782 -0.028676" rpy="0 0 0" />
      <mass value="0.14433" />
      <inertia ixx="3.6119E-05" ixy="-1.3242E-06" ixz="-3.2733E-08" iyy="3.4626E-05" iyz="7.6694E-09" izz="6.1463E-05" />
    </inertial>
    <visual>
      <origin xyz="0 0 0" rpy="0 0 0" />
      <geometry>
        <mesh filename="../meshes/Link7.STL" />
      </geometry>
      <material name="">
        <color rgba="1 1 1 1" />
      </material>
    </visual>
    <collision>
      <origin xyz="0 0 0" rpy="0 0 0" />
      <geometry>
        <mesh filename="../meshes/Link7.STL" />
      </geometry>
    </collision>
  </link>

  <joint name="left_joint7" type="revolute">
    <origin xyz="0 0 0.1725" rpy="0 0 0" />
    <parent link="left_Link6" />
    <child link="left_Link7" />
    <axis xyz="0 0 1" />
    <limit lower="-6.283" upper="6.283" effort="100" velocity="1" />
  </joint>

  <link name="left_tool_hand">
    <inertial>
      <origin xyz="0.0 0.0 0.0" rpy="0 0 0" />
      <mass value="0.01"/>
      <inertia ixx="0.0001" ixy="0" ixz="0" iyy="0.0001" iyz="0" izz="0.0001"/>
    </inertial>
  </link>
  <joint name="left_joint_hand" type="fixed">
    <origin xyz="0 0 0.10" rpy="0 0 2.617" />
    <parent link="left_Link7" />
    <child link="left_tool_hand" />
  </joint>

  <link name="left_right_robotiq">
    <inertial>
      <origin xyz="0.0 0.0 0.0" rpy="0 0 0" />
      <mass value="0.01"/>
      <inertia ixx="0.0001" ixy="0" ixz="0" iyy="0.0001" iyz="0" izz="0.0001"/>
    </inertial>
  </link>
  <joint name="left_right_joint_robotiq" type="fixed">
    <origin xyz="0 0 0.206" rpy="3.14 -0.942 -1.57" />
    <parent link="left_Link7" />
    <child link="left_right_robotiq" />
  </joint>

  <link name="left_left_robotiq">
    <inertial>
      <origin xyz="0.0 0.0 0.0" rpy="0 0 0" />
      <mass value="0.01"/>
      <inertia ixx="0.0001" ixy="0" ixz="0" iyy="0.0001" iyz="0" izz="0.0001"/>
    </inertial>
  </link>
  <joint name="left_left_joint_robotiq" type="fixed">
    <origin xyz="0 0 0.19182" rpy="0 0 -1.8325" />
    <parent link="left_Link7" />
    <child link="left_left_robotiq" />
  </joint>

  <link name="left_f_sensor">
    <inertial>
      <origin xyz="0.0 0.0 0.0" rpy="0 0 0" />
      <mass value="0.01"/>
      <inertia ixx="0.0001" ixy="0" ixz="0" iyy="0.0001" iyz="0" izz="0.0001"/>
    </inertial>
  </link>
  <joint name="left_joint_f_sensor" type="fixed">
    <origin xyz="0 0 0.02075" rpy="0 0 3.141" />
    <parent link="left_Link7" />
    <child link="left_f_sensor" />
  </joint>


  <joint name="right_base_mounting_joint" type="fixed">
    <origin xyz="0 -0.1 0" rpy="1.5708 -1.5708 0.4363" />
    <parent link="torso_base_link" />
    <child link="right_base_link" />
  </joint>

  <link name="right_base_link">
    <inertial>
      <origin xyz="0.00043296 3.5291E-05 0.059942" rpy="0 0 0" />
      <mass value="0.84105" />
      <inertia ixx="0.0017261" ixy="2.5275E-06" ixz="3.6769E-05" iyy="0.0017099" iyz="-1.68E-06" izz="0.00090402" />
    </inertial>
    <visual>
      <origin xyz="0 0 0" rpy="0 0 0" />
      <geometry>
        <mesh filename="../meshes/base_link.STL" />
      </geometry>
      <material name="">
        <color rgba="1 1 1 1" />
      </material>
    </visual>
    <collision>
      <origin xyz="0 0 0" rpy="0 0 0" />
      <geometry>
        <mesh filename="../meshes/base_link.STL" />
      </geometry>
    </collision>
  </link>

  <link name="right_Link1">
    <inertial>
      <origin xyz="-2.1376E-07 0.025186 -0.021108" rpy="0 0 0" />
      <mass value="0.59356" />
      <inertia ixx="0.0012661" ixy="-9.8019E-09" ixz="-1.2951E-08" iyy="0.00056135" iyz="-0.00021122" izz="0.0011817" />
    </inertial>
    <visual>
      <origin xyz="0 0 0" rpy="0 0 0" />
      <geometry>
        <mesh filename="../meshes/Link1.STL" />
      </geometry>
      <material name="">
        <color rgba="1 1 1 1" />
      </material>
    </visual>
    <collision>
      <origin xyz="0 0 0" rpy="0 0 0" />
      <geometry>
        <mesh filename="../meshes/Link1.STL" />
      </geometry>
    </collision>
  </link>

  <joint name="right_joint1" type="revolute">
    <origin xyz="0 0 0.2405" rpy="-1.5708 0 0" />
    <parent link="right_base_link" />
    <child link="right_Link1" />
    <axis xyz="0 -1 0" />
    <limit lower="-3.107" upper="3.107" effort="100" velocity="1" />
  </joint>

  <link name="right_Link2">
    <inertial>
      <origin xyz="4.1111E-07 0.011078 0.076129" rpy="0 0 0" />
      <mass value="0.43285" />
      <inertia ixx="0.0012584" ixy="5.6315E-09" ixz="1.3348E-09" iyy="0.0012225" iyz="0.000279" izz="0.00031747" />
    </inertial>
    <visual>
      <origin xyz="0 0 0" rpy="0 0 0" />
      <geometry>
        <mesh filename="../meshes/Link2.STL" />
      </geometry>
      <material name="">
        <color rgba="1 1 1 1" />
      </material>
    </visual>
    <collision>
      <origin xyz="0 0 0" rpy="0 0 0" />
      <geometry>
        <mesh filename="../meshes/Link2.STL" />
      </geometry>
    </collision>
  </link>

  <joint name="right_joint2" type="revolute">
    <origin xyz="0 0 0" rpy="1.5708 0 0" />
    <parent link="right_Link1" />
    <child link="right_Link2" />
    <axis xyz="0 1 0" />
    <limit lower="-2.269" upper="2.269" effort="100" velocity="1" />
  </joint>

  <link name="right_Link3">
    <inertial>
      <origin xyz="-4.7932E-07 0.027347 -0.023544" rpy="0 0 0" />
      <mass value="0.43132" />
      <inertia ixx="0.00079433" ixy="1.0334E-08" ixz="-2.329E-09" iyy="0.00031507" iyz="-0.00014262" izz="0.00073037" />
    </inertial>
    <visual>
      <origin xyz="0 0 0" rpy="0 0 0" />
      <geometry>
        <mesh filename="../meshes/Link3.STL" />
      </geometry>
      <material name="">
        <color rgba="1 1 1 1" />
      </material>
    </visual>
    <collision>
      <origin xyz="0 0 0" rpy="0 0 0" />
      <geometry>
        <mesh filename="../meshes/Link3.STL" />
      </geometry>
    </collision>
  </link>

  <joint name="right_joint3" type="revolute">
    <origin xyz="0 0 0.256" rpy="-1.5708 0 0" />
    <parent link="right_Link2" />
    <child link="right_Link3" />
    <axis xyz="0 -1 0" />
    <limit lower="-3.107" upper="3.107" effort="100" velocity="1" />
  </joint>

  <link name="right_Link4">
    <inertial>
      <origin xyz="5.0444E-06 0.010569 0.059593" rpy="0 0 0" />
      <mass value="0.28963" />
      <inertia ixx="0.00063737" ixy="-3.8666E-08" ixz="7.0522E-08" iyy="0.00061418" iyz="0.00014461" izz="0.00015648" />
    </inertial>
    <visual>
      <origin xyz="0 0 0" rpy="0 0 0" />
      <geometry>
        <mesh filename="../meshes/Link4.STL" />
      </geometry>
      <material name="">
        <color rgba="1 1 1 1" />
      </material>
    </visual>
    <collision>
      <origin xyz="0 0 0" rpy="0 0 0" />
      <geometry>
        <mesh filename="../meshes/Link4.STL" />
      </geometry>
    </collision>
  </link>

  <joint name="right_joint4" type="revolute">
    <origin xyz="0 0 0" rpy="1.5708 0 0" />
    <parent link="right_Link3" />
    <child link="right_Link4" />
    <axis xyz="0 1 0" />
    <limit lower="-2.356" upper="2.356" effort="100" velocity="1" />
  </joint>

  <link name="right_Link5">
    <inertial>
      <origin xyz="1.1466E-06 0.021541 -0.018041" rpy="0 0 0" />
      <mass value="0.23941" />
      <inertia ixx="0.00028594" ixy="1.8435E-09" ixz="2.6611E-09" iyy="0.00011989" iyz="-4.4238E-05" izz="0.00026273" />
    </inertial>
    <visual>
      <origin xyz="0 0 0" rpy="0 0 0" />
      <geometry>
        <mesh filename="../meshes/Link5.STL" />
      </geometry>
      <material name="">
        <color rgba="1 1 1 1" />
      </material>
    </visual>
    <collision>
      <origin xyz="0 0 0" rpy="0 0 0" />
      <geometry>
        <mesh filename="../meshes/Link5.STL" />
      </geometry>
    </collision>
  </link>

  <joint name="right_joint5" type="revolute">
    <origin xyz="0 0 0.21" rpy="-1.5708 0 0" />
    <parent link="right_Link4" />
    <child link="right_Link5" />
    <axis xyz="0 -1 0" />
    <limit lower="-3.107" upper="3.107" effort="100" velocity="1" />
  </joint>

  <link name="right_Link6">
    <inertial>
      <origin xyz="4.5754E-06 0.0073681 0.059382" rpy="0 0 0" />
      <mass value="0.21879" />
      <inertia ixx="0.00035053" ixy="-1.7437E-08" ixz="3.1653E-08" iyy="0.00033447" iyz="7.824E-05" izz="0.00010492" />
    </inertial>
    <visual>
      <origin xyz="0 0 0" rpy="0 0 0" />
      <geometry>
        <mesh filename="../meshes/Link6.STL" />
      </geometry>
      <material name="">
        <color rgba="1 1 1 1" />
      </material>
    </visual>
    <collision>
      <origin xyz="0 0 0" rpy="0 0 0" />
      <geometry>
        <mesh filename="../meshes/Link6.STL" />
      </geometry>
    </collision>
  </link>

  <joint name="right_joint6" type="revolute">
    <origin xyz="0 0 0" rpy="1.5708 0 0" />
    <parent link="right_Link5" />
    <child link="right_Link6" />
    <axis xyz="0 1 0" />
    <limit lower="-2.234" upper="2.234" effort="100" velocity="1" />
  </joint>

  <link name="right_Link7">
    <inertial>
      <origin xyz="0.00032231 -0.0001782 -0.028676" rpy="0 0 0" />
      <mass value="0.14433" />
      <inertia ixx="3.6119E-05" ixy="-1.3242E-06" ixz="-3.2733E-08" iyy="3.4626E-05" iyz="7.6694E-09" izz="6.1463E-05" />
    </inertial>
    <visual>
      <origin xyz="0 0 0" rpy="0 0 0" />
      <geometry>
        <mesh filename="../meshes/Link7.STL" />
      </geometry>
      <material name="">
        <color rgba="1 1 1 1" />
      </material>
    </visual>
    <collision>
      <origin xyz="0 0 0" rpy="0 0 0" />
      <geometry>
        <mesh filename="../meshes/Link7.STL" />
      </geometry>
    </collision>
  </link>

  <joint name="right_joint7" type="revolute">
    <origin xyz="0 0 0.1725" rpy="0 0 0" />
    <parent link="right_Link6" />
    <child link="right_Link7" />
    <axis xyz="0 0 1" />
    <limit lower="-6.283" upper="6.283" effort="100" velocity="1" />
  </joint>

  <link name="right_tool_hand">
    <inertial>
      <origin xyz="0.0 0.0 0.0" rpy="0 0 0" />
      <mass value="0.01"/>
      <inertia ixx="0.0001" ixy="0" ixz="0" iyy="0.0001" iyz="0" izz="0.0001"/>
    </inertial>
  </link>
  <joint name="right_joint_hand" type="fixed">
    <origin xyz="0 0 0.10" rpy="0 0 2.617" />
    <parent link="right_Link7" />
    <child link="right_tool_hand" />
  </joint>

  <link name="right_right_robotiq">
    <inertial>
      <origin xyz="0.0 0.0 0.0" rpy="0 0 0" />
      <mass value="0.01"/>
      <inertia ixx="0.0001" ixy="0" ixz="0" iyy="0.0001" iyz="0" izz="0.0001"/>
    </inertial>
  </link>
  <joint name="right_right_joint_robotiq" type="fixed">
    <origin xyz="0 0 0.206" rpy="3.14 -0.942 -1.57" />
    <parent link="right_Link7" />
    <child link="right_right_robotiq" />
  </joint>

  <link name="right_left_robotiq">
    <inertial>
      <origin xyz="0.0 0.0 0.0" rpy="0 0 0" />
      <mass value="0.01"/>
      <inertia ixx="0.0001" ixy="0" ixz="0" iyy="0.0001" iyz="0" izz="0.0001"/>
    </inertial>
  </link>
  <joint name="right_left_joint_robotiq" type="fixed">
    <origin xyz="0 0 0.19182" rpy="0 0 -1.8325" />
    <parent link="right_Link7" />
    <child link="right_left_robotiq" />
  </joint>

  <link name="right_f_sensor">
    <inertial>
      <origin xyz="0.0 0.0 0.0" rpy="0 0 0" />
      <mass value="0.01"/>
      <inertia ixx="0.0001" ixy="0" ixz="0" iyy="0.0001" iyz="0" izz="0.0001"/>
    </inertial>
  </link>
  <joint name="right_joint_f_sensor" type="fixed">
    <origin xyz="0 0 0.02075" rpy="0 0 3.141" />
    <parent link="right_Link7" />
    <child link="right_f_sensor" />
  </joint>

</robot>